[2025-07-17T09:37:31.590+0000] {local_task_job_runner.py:123} INFO - ::group::Pre task execution logs
[2025-07-17T09:37:31.600+0000] {taskinstance.py:2603} INFO - Dependencies all met for dep_context=non-requeueable deps ti=<TaskInstance: enhanced_csv_json_merge_pipeline.insert_postgres manual__2025-07-17T09:29:49.100537+00:00 [queued]>
[2025-07-17T09:37:31.605+0000] {taskinstance.py:2603} INFO - Dependencies all met for dep_context=requeueable deps ti=<TaskInstance: enhanced_csv_json_merge_pipeline.insert_postgres manual__2025-07-17T09:29:49.100537+00:00 [queued]>
[2025-07-17T09:37:31.606+0000] {taskinstance.py:2856} INFO - Starting attempt 2 of 2
[2025-07-17T09:37:31.611+0000] {taskinstance.py:2879} INFO - Executing <Task(PythonOperator): insert_postgres> on 2025-07-17 09:29:49.100537+00:00
[2025-07-17T09:37:31.614+0000] {warnings.py:112} WARNING - /home/***/.local/lib/python3.12/site-packages/***/task/task_runner/standard_task_runner.py:70: DeprecationWarning: This process (pid=63) is multi-threaded, use of fork() may lead to deadlocks in the child.
  pid = os.fork()

[2025-07-17T09:37:31.615+0000] {standard_task_runner.py:72} INFO - Started process 65 to run task
[2025-07-17T09:37:31.616+0000] {standard_task_runner.py:104} INFO - Running: ['***', 'tasks', 'run', 'enhanced_csv_json_merge_pipeline', 'insert_postgres', 'manual__2025-07-17T09:29:49.100537+00:00', '--job-id', '10', '--raw', '--subdir', 'DAGS_FOLDER/enhanced_csv_json_merge_dag.py', '--cfg-path', '/tmp/tmp8rw1lg8x']
[2025-07-17T09:37:31.616+0000] {standard_task_runner.py:105} INFO - Job 10: Subtask insert_postgres
[2025-07-17T09:37:31.639+0000] {task_command.py:467} INFO - Running <TaskInstance: enhanced_csv_json_merge_pipeline.insert_postgres manual__2025-07-17T09:29:49.100537+00:00 [running]> on host 22ee6e320f38
[2025-07-17T09:37:31.671+0000] {taskinstance.py:3122} INFO - Exporting env vars: AIRFLOW_CTX_DAG_OWNER='***' AIRFLOW_CTX_DAG_ID='enhanced_csv_json_merge_pipeline' AIRFLOW_CTX_TASK_ID='insert_postgres' AIRFLOW_CTX_EXECUTION_DATE='2025-07-17T09:29:49.100537+00:00' AIRFLOW_CTX_TRY_NUMBER='2' AIRFLOW_CTX_DAG_RUN_ID='manual__2025-07-17T09:29:49.100537+00:00'
[2025-07-17T09:37:31.672+0000] {logging_mixin.py:190} INFO - Task instance is in running state
[2025-07-17T09:37:31.672+0000] {logging_mixin.py:190} INFO -  Previous state of the Task instance: queued
[2025-07-17T09:37:31.673+0000] {logging_mixin.py:190} INFO - Current task name:insert_postgres state:running start_date:2025-07-17 09:37:31.601116+00:00
[2025-07-17T09:37:31.674+0000] {logging_mixin.py:190} INFO - Dag name:enhanced_csv_json_merge_pipeline and current dag run status:running
[2025-07-17T09:37:31.674+0000] {taskinstance.py:731} INFO - ::endgroup::
[2025-07-17T09:37:31.683+0000] {taskinstance.py:3301} ERROR - Task failed with exception
Traceback (most recent call last):
  File "/home/airflow/.local/lib/python3.12/site-packages/airflow/models/taskinstance.py", line 767, in _execute_task
    result = _execute_callable(context=context, **execute_callable_kwargs)
             ^^^^^^^^^^^^^^^^^^^^^^^^^^^^^^^^^^^^^^^^^^^^^^^^^^^^^^^^^^^^^
  File "/home/airflow/.local/lib/python3.12/site-packages/airflow/models/taskinstance.py", line 733, in _execute_callable
    return ExecutionCallableRunner(
           ^^^^^^^^^^^^^^^^^^^^^^^^
  File "/home/airflow/.local/lib/python3.12/site-packages/airflow/utils/operator_helpers.py", line 252, in run
    return self.func(*args, **kwargs)
           ^^^^^^^^^^^^^^^^^^^^^^^^^^
  File "/home/airflow/.local/lib/python3.12/site-packages/airflow/models/baseoperator.py", line 406, in wrapper
    return func(self, *args, **kwargs)
           ^^^^^^^^^^^^^^^^^^^^^^^^^^^
  File "/home/airflow/.local/lib/python3.12/site-packages/airflow/operators/python.py", line 238, in execute
    return_value = self.execute_callable()
                   ^^^^^^^^^^^^^^^^^^^^^^^
  File "/home/airflow/.local/lib/python3.12/site-packages/airflow/operators/python.py", line 256, in execute_callable
    return runner.run(*self.op_args, **self.op_kwargs)
           ^^^^^^^^^^^^^^^^^^^^^^^^^^^^^^^^^^^^^^^^^^^
  File "/home/airflow/.local/lib/python3.12/site-packages/airflow/utils/operator_helpers.py", line 252, in run
    return self.func(*args, **kwargs)
           ^^^^^^^^^^^^^^^^^^^^^^^^^^
  File "/opt/airflow/dags/enhanced_csv_json_merge_dag.py", line 45, in insert_into_postgres
    cur.execute("INSERT INTO department (name) VALUES (%s) ON CONFLICT (name) DO NOTHING", (row["department"],))
psycopg2.errors.UndefinedTable: relation "department" does not exist
LINE 1: INSERT INTO department (name) VALUES ('Engineering') ON CONF...
                    ^

[2025-07-17T09:37:31.688+0000] {logging_mixin.py:190} INFO - Task instance in failure state
[2025-07-17T09:37:31.689+0000] {logging_mixin.py:190} INFO - Task start:2025-07-17 09:37:31.601116+00:00 end:2025-07-17 09:37:31.688415+00:00 duration:0.087299
[2025-07-17T09:37:31.690+0000] {logging_mixin.py:190} INFO - Task:<Task(PythonOperator): insert_postgres> dag:<DAG: enhanced_csv_json_merge_pipeline> dagrun:<DagRun enhanced_csv_json_merge_pipeline @ 2025-07-17 09:29:49.100537+00:00: manual__2025-07-17T09:29:49.100537+00:00, state:running, queued_at: 2025-07-17 09:29:49.115718+00:00. externally triggered: True>
[2025-07-17T09:37:31.690+0000] {logging_mixin.py:190} INFO - Failure caused by relation "department" does not exist
LINE 1: INSERT INTO department (name) VALUES ('Engineering') ON CONF...
                    ^
[2025-07-17T09:37:31.690+0000] {taskinstance.py:1225} INFO - Marking task as FAILED. dag_id=enhanced_csv_json_merge_pipeline, task_id=insert_postgres, run_id=manual__2025-07-17T09:29:49.100537+00:00, execution_date=20250717T092949, start_date=20250717T093731, end_date=20250717T093731
[2025-07-17T09:37:31.696+0000] {taskinstance.py:340} INFO - ::group::Post task execution logs
[2025-07-17T09:37:31.697+0000] {standard_task_runner.py:124} ERROR - Failed to execute job 10 for task insert_postgres (relation "department" does not exist
LINE 1: INSERT INTO department (name) VALUES ('Engineering') ON CONF...
                    ^
; 65)
Traceback (most recent call last):
  File "/home/airflow/.local/lib/python3.12/site-packages/airflow/task/task_runner/standard_task_runner.py", line 117, in _start_by_fork
    ret = args.func(args, dag=self.dag)
          ^^^^^^^^^^^^^^^^^^^^^^^^^^^^^
  File "/home/airflow/.local/lib/python3.12/site-packages/airflow/cli/cli_config.py", line 49, in command
    return func(*args, **kwargs)
           ^^^^^^^^^^^^^^^^^^^^^
  File "/home/airflow/.local/lib/python3.12/site-packages/airflow/utils/cli.py", line 115, in wrapper
    return f(*args, **kwargs)
           ^^^^^^^^^^^^^^^^^^
  File "/home/airflow/.local/lib/python3.12/site-packages/airflow/cli/commands/task_command.py", line 483, in task_run
    task_return_code = _run_task_by_selected_method(args, _dag, ti)
                       ^^^^^^^^^^^^^^^^^^^^^^^^^^^^^^^^^^^^^^^^^^^^
  File "/home/airflow/.local/lib/python3.12/site-packages/airflow/cli/commands/task_command.py", line 256, in _run_task_by_selected_method
    return _run_raw_task(args, ti)
           ^^^^^^^^^^^^^^^^^^^^^^^
  File "/home/airflow/.local/lib/python3.12/site-packages/airflow/cli/commands/task_command.py", line 341, in _run_raw_task
    return ti._run_raw_task(
           ^^^^^^^^^^^^^^^^^
  File "/home/airflow/.local/lib/python3.12/site-packages/airflow/utils/session.py", line 97, in wrapper
    return func(*args, session=session, **kwargs)
           ^^^^^^^^^^^^^^^^^^^^^^^^^^^^^^^^^^^^^^
  File "/home/airflow/.local/lib/python3.12/site-packages/airflow/models/taskinstance.py", line 2995, in _run_raw_task
    return _run_raw_task(
           ^^^^^^^^^^^^^^
  File "/home/airflow/.local/lib/python3.12/site-packages/airflow/models/taskinstance.py", line 273, in _run_raw_task
    TaskInstance._execute_task_with_callbacks(
  File "/home/airflow/.local/lib/python3.12/site-packages/airflow/models/taskinstance.py", line 3149, in _execute_task_with_callbacks
    result = self._execute_task(context, task_orig)
             ^^^^^^^^^^^^^^^^^^^^^^^^^^^^^^^^^^^^^^
  File "/home/airflow/.local/lib/python3.12/site-packages/airflow/models/taskinstance.py", line 3173, in _execute_task
    return _execute_task(self, context, task_orig)
           ^^^^^^^^^^^^^^^^^^^^^^^^^^^^^^^^^^^^^^^
  File "/home/airflow/.local/lib/python3.12/site-packages/airflow/models/taskinstance.py", line 767, in _execute_task
    result = _execute_callable(context=context, **execute_callable_kwargs)
             ^^^^^^^^^^^^^^^^^^^^^^^^^^^^^^^^^^^^^^^^^^^^^^^^^^^^^^^^^^^^^
  File "/home/airflow/.local/lib/python3.12/site-packages/airflow/models/taskinstance.py", line 733, in _execute_callable
    return ExecutionCallableRunner(
           ^^^^^^^^^^^^^^^^^^^^^^^^
  File "/home/airflow/.local/lib/python3.12/site-packages/airflow/utils/operator_helpers.py", line 252, in run
    return self.func(*args, **kwargs)
           ^^^^^^^^^^^^^^^^^^^^^^^^^^
  File "/home/airflow/.local/lib/python3.12/site-packages/airflow/models/baseoperator.py", line 406, in wrapper
    return func(self, *args, **kwargs)
           ^^^^^^^^^^^^^^^^^^^^^^^^^^^
  File "/home/airflow/.local/lib/python3.12/site-packages/airflow/operators/python.py", line 238, in execute
    return_value = self.execute_callable()
                   ^^^^^^^^^^^^^^^^^^^^^^^
  File "/home/airflow/.local/lib/python3.12/site-packages/airflow/operators/python.py", line 256, in execute_callable
    return runner.run(*self.op_args, **self.op_kwargs)
           ^^^^^^^^^^^^^^^^^^^^^^^^^^^^^^^^^^^^^^^^^^^
  File "/home/airflow/.local/lib/python3.12/site-packages/airflow/utils/operator_helpers.py", line 252, in run
    return self.func(*args, **kwargs)
           ^^^^^^^^^^^^^^^^^^^^^^^^^^
  File "/opt/airflow/dags/enhanced_csv_json_merge_dag.py", line 45, in insert_into_postgres
    cur.execute("INSERT INTO department (name) VALUES (%s) ON CONFLICT (name) DO NOTHING", (row["department"],))
psycopg2.errors.UndefinedTable: relation "department" does not exist
LINE 1: INSERT INTO department (name) VALUES ('Engineering') ON CONF...
                    ^

[2025-07-17T09:37:31.716+0000] {local_task_job_runner.py:261} INFO - Task exited with return code 1
[2025-07-17T09:37:31.725+0000] {taskinstance.py:3891} INFO - 0 downstream tasks scheduled from follow-on schedule check
[2025-07-17T09:37:31.725+0000] {local_task_job_runner.py:240} INFO - ::endgroup::
